# defer and errdefer
     
`defer` will execute an expression at the end of the current scope.
  
The `errdefer` keyword is similar to `defer`, but will only execute if the scope returns with an `error`.
  
This is especially useful in allowing a function to clean up properly on error, and replaces 'goto error handling' tactics as seen in C.
  
Inside a `defer` expression, `return` is not allowed.
  
**ZigC**
```
from std.testing import expect;
from std.debug import print;

size_t! deferExample() {
    size_t a = 1;

    {
        defer a = 2;
        a = 1;
    }
    try expect(a == 2);

    a = 5;
    return a;
}

test "defer basics" {
    try expect((try deferExample()) == 5);
}

void deferUnwindExample() {
    print("\n"); // removed {}, varags issue

    defer {
        print("1 ");
    }
    defer {
        print("2 ");
    }
    if (false) {
        defer {
            print("3 "); // this is not called
        }
    }
}

test "defer unwinding" {
    deferUnwindExample(); // prints 2 1
}

void! deferErrorExample(bool is_error) {
    print("\nstart of function\n");

    defer {
        print("end of function\n");
    }

    errdefer {
        print("encountered an error!\n");

    if (is_error) {
        return error.DeferError;
    }
}

void! deferErrorCaptureExample() {
    errdefer (err) {
        std.debug.print("the error is {s}\n", @errorName(err));
    }

    return error.DeferError;
}

test "errdefer unwinding" {
    deferErrorExample(false) catch {};
    deferErrorExample(true) catch {};
    deferErrorCaptureExample() catch {};
}
```
  
**Zig**
```
const std = @import("std");
const expect = std.testing.expect;
const print = std.debug.print;

fn deferExample() !usize {
    var a: usize = 1;

    {
        defer a = 2;
        a = 1;
    }
    try expect(a == 2);

    a = 5;
    return a;
}

test "defer basics" {
    try expect((try deferExample()) == 5);
}

fn deferUnwindExample() void {
    print("\n", .{});

    defer {
        print("1 ", .{});
    }
    defer {
        print("2 ", .{});
    }
    if (false) {
        defer {
            print("3 ", .{}); // not called
        }
    }
}

test "defer unwinding" {
    deferUnwindExample();
}

fn deferErrorExample(is_error: bool) !void {
    print("\nstart of function\n", .{});

    defer {
        print("end of function\n", .{});
    }

    errdefer {
        print("encountered an error!\n", .{});
    }

    if (is_error) {
        return error.DeferError;
    }
}

fn deferErrorCaptureExample() !void {
    errdefer |err| {
        std.debug.print("the error is {s}\n", .{@errorName(err)});
    }

    return error.DeferError;
}

test "errdefer unwinding" {
    deferErrorExample(false) catch {};
    deferErrorExample(true) catch {};
    deferErrorCaptureExample() catch {};
}
```
